<robot name="my_robot" version="1.0">
  <joint name="link1_motor_joint" type="fixed">
    <origin rpy="0.00000 0.00000 0.00000" xyz="0.00000 -0.00000 0.02630"/>
    <parent link="base_link"/>
    <child link="link1_motor"/>
    <axis xyz="0.00000 0.00000 1.00000"/>
  </joint>
  <joint name="link1_1_joint" type="revolute">
    <limit lower="-3.14000" upper="3.14000" effort="0.00000" velocity="0.00000"/>
    <origin rpy="0.00000 0.00000 0.00000" xyz="0.00000 0.00000 0.05070"/>
    <parent link="link1_motor"/>
    <child link="link1_1"/>
    <axis xyz="0.00000 0.00000 1.00000"/>
  </joint>
  <joint name="link4_motor_joint" type="fixed">
    <origin rpy="0.00000 0.00000 0.00000" xyz="0.00400 0.00000 0.05460"/>
    <parent link="link3_2"/>
    <child link="link4_motor"/>
  </joint>
  <joint name="link4_1_joint" type="revolute">
    <limit lower="-3.14000" upper="3.14000" effort="0.00000" velocity="0.00000"/>
    <origin rpy="0.00000 0.00000 0.00000" xyz="-0.00650 0.00000 0.00000"/>
    <parent link="link4_motor"/>
    <child link="link4_1"/>
    <axis xyz="-1.00000 0.00000 0.00000"/>
  </joint>
  <joint name="link4_1.000_joint" type="fixed">
    <origin rpy="0.00000 0.00000 0.00000" xyz="-0.01500 0.00000 0.00000"/>
    <parent link="link4_1"/>
    <child link="link4_2"/>
  </joint>
  <joint name="link4_3_joint" type="fixed">
    <origin rpy="0.00000 0.00000 0.00000" xyz="-0.07500 0.00000 0.10000"/>
    <parent link="link4_2"/>
    <child link="link4_3"/>
  </joint>
  <joint name="link5_motor_joint" type="fixed">
    <origin rpy="0.00000 0.00000 0.00000" xyz="0.00000 0.00000 0.02000"/>
    <parent link="link4_3"/>
    <child link="link5_motor"/>
  </joint>
  <joint name="link5_1_joint" type="revolute">
    <limit lower="-3.14000" upper="3.14000" effort="0.00000" velocity="0.00000"/>
    <origin rpy="0.00000 0.00000 0.00000" xyz="0.00000 0.00000 0.02900"/>
    <parent link="link5_motor"/>
    <child link="link5_1"/>
    <axis xyz="0.00000 0.00000 1.00000"/>
  </joint>
  <joint name="link5_2_joint" type="fixed">
    <origin rpy="0.00000 0.00000 0.00000" xyz="0.00000 0.00000 0.02000"/>
    <parent link="link5_1"/>
    <child link="link5_2"/>
  </joint>
  <joint name="link6_motor_joint" type="fixed">
    <origin rpy="0.00000 0.00000 0.00000" xyz="0.00350 0.00000 0.04950"/>
    <parent link="link5_2"/>
    <child link="link6_motor"/>
  </joint>
  <joint name="link6_1_joint" type="revolute">
    <limit lower="-3.14000" upper="3.14000" effort="0.00000" velocity="0.00000"/>
    <origin rpy="0.00000 0.00000 0.00000" xyz="0.00200 0.00000 0.00000"/>
    <parent link="link6_motor"/>
    <child link="link6_1"/>
    <axis xyz="1.00000 0.00000 0.00000"/>
  </joint>
  <joint name="link1_2_joint" type="fixed">
    <origin rpy="0.00000 0.00000 0.00000" xyz="0.00000 0.00000 0.01500"/>
    <parent link="link1_1"/>
    <child link="link1_2"/>
  </joint>
  <joint name="link2_motor_joint" type="fixed">
    <origin rpy="0.00000 0.00000 0.00000" xyz="0.00000 0.00000 0.05900"/>
    <parent link="link1_2"/>
    <child link="link2_motor"/>
  </joint>
  <joint name="link2_1_joint" type="revolute">
    <limit lower="-3.14000" upper="3.14000" effort="0.00000" velocity="0.00000"/>
    <origin rpy="0.00000 0.00000 0.00000" xyz="0.00900 0.00000 0.00000"/>
    <parent link="link2_motor"/>
    <child link="link2_1"/>
    <axis xyz="1.00000 0.00000 0.00000"/>
  </joint>
  <joint name="link2_2_joint" type="fixed">
    <origin rpy="0.00000 0.00000 0.00000" xyz="0.01500 0.00000 0.00000"/>
    <parent link="link2_1"/>
    <child link="link2_2"/>
  </joint>
  <joint name="link2_3_joint" type="fixed">
    <origin rpy="0.00000 0.00000 0.00000" xyz="0.07500 0.00000 0.13000"/>
    <parent link="link2_2"/>
    <child link="link2_3"/>
  </joint>
  <joint name="link3_motor_joint" type="fixed">
    <origin rpy="0.00000 0.00000 0.00000" xyz="0.00000 0.00000 0.02100"/>
    <parent link="link2_3"/>
    <child link="link3_motor"/>
  </joint>
  <joint name="link3_1_joint" type="revolute">
    <limit lower="-3.14000" upper="3.14000" effort="0.00000" velocity="0.00000"/>
    <origin rpy="0.00000 0.00000 0.00000" xyz="0.00000 0.00000 0.03905"/>
    <parent link="link3_motor"/>
    <child link="link3_1"/>
    <axis xyz="0.00000 0.00000 1.00000"/>
  </joint>
  <joint name="link3_2_joint" type="fixed">
    <origin rpy="0.00000 0.00000 0.00000" xyz="0.00000 0.00000 0.01500"/>
    <parent link="link3_1"/>
    <child link="link3_2"/>
  </joint>
  <link name="base_link">
    <collision name="mesh_base_link_collision">
      <origin rpy="0.00000 0.00000 0.00000" xyz="0.00000 0.00000 0.00000"/>
      <geometry>
        <mesh filename="../meshes/stl/1_my_robot v2_base_link_1_Body1.stl" scale="0.00100 0.00100 0.00100"/>
      </geometry>
    </collision>
    <visual name="mesh_base_link">
      <material name="None"/>
      <origin rpy="0.00000 0.00000 0.00000" xyz="0.00000 0.00000 0.00000"/>
      <geometry>
        <mesh filename="../meshes/stl/1_my_robot v2_base_link_1_Body1.stl" scale="0.00100 0.00100 0.00100"/>
      </geometry>
    </visual>
  </link>
  <link name="link1_motor">
    <collision name="mesh_link1_motor_collision">
      <origin rpy="0.00000 0.00000 0.00000" xyz="0.00000 0.00000 -0.02630"/>
      <geometry>
        <mesh filename="../meshes/stl/1_my_robot v2_link1_motor_1_Body1.stl" scale="0.00100 0.00100 0.00100"/>
      </geometry>
    </collision>
    <visual name="mesh_link1_motor">
      <material name="None"/>
      <origin rpy="0.00000 0.00000 0.00000" xyz="0.00000 0.00000 -0.02630"/>
      <geometry>
        <mesh filename="../meshes/stl/1_my_robot v2_link1_motor_1_Body1.stl" scale="0.00100 0.00100 0.00100"/>
      </geometry>
    </visual>
  </link>
  <link name="link3_2">
    <collision name="mesh_link3_2_collision">
      <origin rpy="0.00000 0.00000 0.00000" xyz="-0.09900 0.00000 -0.35605"/>
      <geometry>
        <mesh filename="../meshes/stl/1_my_robot v2_link3_2_1_Body1.stl" scale="0.00100 0.00100 0.00100"/>
      </geometry>
    </collision>
    <visual name="mesh_link3_2">
      <material name="None"/>
      <origin rpy="0.00000 0.00000 0.00000" xyz="-0.09900 0.00000 -0.35605"/>
      <geometry>
        <mesh filename="../meshes/stl/1_my_robot v2_link3_2_1_Body1.stl" scale="0.00100 0.00100 0.00100"/>
      </geometry>
    </visual>
  </link>
  <link name="link4_motor">
    <collision name="mesh_link4_motor_collision">
      <origin rpy="0.00000 0.00000 0.00000" xyz="-0.10300 0.00000 -0.41065"/>
      <geometry>
        <mesh filename="../meshes/stl/1_my_robot v2_link4_motor_1_Body1.stl" scale="0.00100 0.00100 0.00100"/>
      </geometry>
    </collision>
    <visual name="mesh_link4_motor">
      <material name="None"/>
      <origin rpy="0.00000 0.00000 0.00000" xyz="-0.10300 0.00000 -0.41065"/>
      <geometry>
        <mesh filename="../meshes/stl/1_my_robot v2_link4_motor_1_Body1.stl" scale="0.00100 0.00100 0.00100"/>
      </geometry>
    </visual>
  </link>
  <link name="link4_1">
    <collision name="mesh_link4_1_collision">
      <origin rpy="0.00000 0.00000 0.00000" xyz="-0.09650 0.00000 -0.41065"/>
      <geometry>
        <mesh filename="../meshes/stl/1_my_robot v2_link4_1_1_Body1.stl" scale="0.00100 0.00100 0.00100"/>
      </geometry>
    </collision>
    <visual name="mesh_link4_1">
      <material name="None"/>
      <origin rpy="0.00000 0.00000 0.00000" xyz="-0.09650 0.00000 -0.41065"/>
      <geometry>
        <mesh filename="../meshes/stl/1_my_robot v2_link4_1_1_Body1.stl" scale="0.00100 0.00100 0.00100"/>
      </geometry>
    </visual>
  </link>
  <link name="link4_2">
    <collision name="mesh_link4_2_collision">
      <origin rpy="0.00000 0.00000 0.00000" xyz="-0.08150 0.00000 -0.41065"/>
      <geometry>
        <mesh filename="../meshes/stl/1_my_robot v2_link4_PLA_1_Body1.stl" scale="0.00100 0.00100 0.00100"/>
      </geometry>
    </collision>
    <visual name="mesh_link4_2">
      <material name="None"/>
      <origin rpy="0.00000 0.00000 0.00000" xyz="-0.08150 0.00000 -0.41065"/>
      <geometry>
        <mesh filename="../meshes/stl/1_my_robot v2_link4_PLA_1_Body1.stl" scale="0.00100 0.00100 0.00100"/>
      </geometry>
    </visual>
  </link>
  <link name="link4_3">
    <collision name="mesh_link4_3_collision">
      <origin rpy="0.00000 0.00000 0.00000" xyz="-0.00650 0.00000 -0.51065"/>
      <geometry>
        <mesh filename="../meshes/stl/1_my_robot v2_link4_7_1_Body1.stl" scale="0.00100 0.00100 0.00100"/>
      </geometry>
    </collision>
    <visual name="mesh_link4_3">
      <material name="None"/>
      <origin rpy="0.00000 0.00000 0.00000" xyz="-0.00650 0.00000 -0.51065"/>
      <geometry>
        <mesh filename="../meshes/stl/1_my_robot v2_link4_7_1_Body1.stl" scale="0.00100 0.00100 0.00100"/>
      </geometry>
    </visual>
  </link>
  <link name="link5_motor">
    <collision name="mesh_link5_motor_collision">
      <origin rpy="0.00000 0.00000 0.00000" xyz="-0.00650 0.00000 -0.53065"/>
      <geometry>
        <mesh filename="../meshes/stl/1_my_robot v2_link5_motor_1_Body1.stl" scale="0.00100 0.00100 0.00100"/>
      </geometry>
    </collision>
    <visual name="mesh_link5_motor">
      <material name="None"/>
      <origin rpy="0.00000 0.00000 0.00000" xyz="-0.00650 0.00000 -0.53065"/>
      <geometry>
        <mesh filename="../meshes/stl/1_my_robot v2_link5_motor_1_Body1.stl" scale="0.00100 0.00100 0.00100"/>
      </geometry>
    </visual>
  </link>
  <link name="link5_1">
    <collision name="mesh_link5_1_collision">
      <origin rpy="0.00000 0.00000 0.00000" xyz="-0.00650 0.00000 -0.55965"/>
      <geometry>
        <mesh filename="../meshes/stl/1_my_robot v2_link5_1_1_Body1.stl" scale="0.00100 0.00100 0.00100"/>
      </geometry>
    </collision>
    <visual name="mesh_link5_1">
      <material name="None"/>
      <origin rpy="0.00000 0.00000 0.00000" xyz="-0.00650 0.00000 -0.55965"/>
      <geometry>
        <mesh filename="../meshes/stl/1_my_robot v2_link5_1_1_Body1.stl" scale="0.00100 0.00100 0.00100"/>
      </geometry>
    </visual>
  </link>
  <link name="link5_2">
    <collision name="mesh_link5_2_collision">
      <origin rpy="0.00000 0.00000 0.00000" xyz="-0.00650 0.00000 -0.57965"/>
      <geometry>
        <mesh filename="../meshes/stl/1_my_robot v2_link5_2_1_Body2.stl" scale="0.00100 0.00100 0.00100"/>
      </geometry>
    </collision>
    <visual name="mesh_link5_2">
      <material name="None"/>
      <origin rpy="0.00000 0.00000 0.00000" xyz="-0.00650 0.00000 -0.57965"/>
      <geometry>
        <mesh filename="../meshes/stl/1_my_robot v2_link5_2_1_Body2.stl" scale="0.00100 0.00100 0.00100"/>
      </geometry>
    </visual>
  </link>
  <link name="link6_motor">
    <collision name="mesh_link6_motor_collision">
      <origin rpy="0.00000 0.00000 0.00000" xyz="-0.01000 0.00000 -0.62915"/>
      <geometry>
        <mesh filename="../meshes/stl/1_my_robot v2_link6_motor_1_Body1.stl" scale="0.00100 0.00100 0.00100"/>
      </geometry>
    </collision>
    <visual name="mesh_link6_motor">
      <material name="None"/>
      <origin rpy="0.00000 0.00000 0.00000" xyz="-0.01000 0.00000 -0.62915"/>
      <geometry>
        <mesh filename="../meshes/stl/1_my_robot v2_link6_motor_1_Body1.stl" scale="0.00100 0.00100 0.00100"/>
      </geometry>
    </visual>
  </link>
  <link name="link6_1">
    <collision name="mesh_link6_1_collision">
      <origin rpy="0.00000 0.00000 0.00000" xyz="-0.01200 0.00000 -0.62915"/>
      <geometry>
        <mesh filename="../meshes/stl/1_my_robot v2_link6_1_1_Body1.stl" scale="0.00100 0.00100 0.00100"/>
      </geometry>
    </collision>
    <visual name="mesh_link6_1">
      <material name="None"/>
      <origin rpy="0.00000 0.00000 0.00000" xyz="-0.01200 0.00000 -0.62915"/>
      <geometry>
        <mesh filename="../meshes/stl/1_my_robot v2_link6_1_1_Body1.stl" scale="0.00100 0.00100 0.00100"/>
      </geometry>
    </visual>
  </link>
  <link name="link1_1">
    <collision name="mesh_link1_1_collision">
      <origin rpy="0.00000 0.00000 0.00000" xyz="0.00000 0.00000 0.00750"/>
      <geometry>
        <box size="0.07000 0.11500 0.01500"/>
      </geometry>
    </collision>
    <visual name="mesh_link1_1">
      <material name="None"/>
      <origin rpy="0.00000 0.00000 0.00000" xyz="0.00000 0.00000 -0.07700"/>
      <geometry>
        <mesh filename="../meshes/stl/1_my_robot v2_link1_1_1_Body1.stl" scale="0.00100 0.00100 0.00100"/>
      </geometry>
    </visual>
  </link>
  <link name="link1_2">
    <collision name="mesh_link1_2_collision">
      <origin rpy="0.00000 0.00000 0.00000" xyz="0.00000 0.00000 -0.09200"/>
      <geometry>
        <mesh filename="../meshes/stl/1_my_robot v2_link1_2_1_Body2.stl" scale="0.00100 0.00100 0.00100"/>
      </geometry>
    </collision>
    <visual name="mesh_link1_2">
      <material name="None"/>
      <origin rpy="0.00000 0.00000 0.00000" xyz="0.00000 0.00000 -0.09200"/>
      <geometry>
        <mesh filename="../meshes/stl/1_my_robot v2_link1_2_1_Body2.stl" scale="0.00100 0.00100 0.00100"/>
      </geometry>
    </visual>
  </link>
  <link name="link2_motor">
    <collision name="mesh_link2_motor_collision">
      <origin rpy="0.00000 0.00000 0.00000" xyz="0.00000 0.00000 -0.15100"/>
      <geometry>
        <mesh filename="../meshes/stl/1_my_robot v2_link2_motor_1_Body1.stl" scale="0.00100 0.00100 0.00100"/>
      </geometry>
    </collision>
    <visual name="mesh_link2_motor">
      <material name="None"/>
      <origin rpy="0.00000 0.00000 0.00000" xyz="0.00000 0.00000 -0.15100"/>
      <geometry>
        <mesh filename="../meshes/stl/1_my_robot v2_link2_motor_1_Body1.stl" scale="0.00100 0.00100 0.00100"/>
      </geometry>
    </visual>
  </link>
  <link name="link2_1">
    <collision name="mesh_link2_1_collision">
      <origin rpy="0.00000 0.00000 0.00000" xyz="-0.00900 0.00000 -0.15100"/>
      <geometry>
        <mesh filename="../meshes/stl/1_my_robot v2_link2_1_1_Body1.stl" scale="0.00100 0.00100 0.00100"/>
      </geometry>
    </collision>
    <visual name="mesh_link2_1">
      <material name="None"/>
      <origin rpy="0.00000 0.00000 0.00000" xyz="-0.00900 0.00000 -0.15100"/>
      <geometry>
        <mesh filename="../meshes/stl/1_my_robot v2_link2_1_1_Body1.stl" scale="0.00100 0.00100 0.00100"/>
      </geometry>
    </visual>
  </link>
  <link name="link2_2">
    <collision name="mesh_link2_2_collision">
      <origin rpy="0.00000 0.00000 0.00000" xyz="-0.02400 0.00000 -0.15100"/>
      <geometry>
        <mesh filename="../meshes/stl/1_my_robot v2_link2_PLA_1_Body1.stl" scale="0.00100 0.00100 0.00100"/>
      </geometry>
    </collision>
    <visual name="mesh_link2_2">
      <material name="None"/>
      <origin rpy="0.00000 0.00000 0.00000" xyz="-0.02400 0.00000 -0.15100"/>
      <geometry>
        <mesh filename="../meshes/stl/1_my_robot v2_link2_PLA_1_Body1.stl" scale="0.00100 0.00100 0.00100"/>
      </geometry>
    </visual>
  </link>
  <link name="link2_3">
    <collision name="mesh_link2_3_collision">
      <origin rpy="0.00000 0.00000 0.00000" xyz="-0.09900 0.00000 -0.28100"/>
      <geometry>
        <mesh filename="../meshes/stl/1_my_robot v2_link2_7_1_Body1.stl" scale="0.00100 0.00100 0.00100"/>
      </geometry>
    </collision>
    <visual name="mesh_link2_3">
      <material name="None"/>
      <origin rpy="0.00000 0.00000 0.00000" xyz="-0.09900 0.00000 -0.28100"/>
      <geometry>
        <mesh filename="../meshes/stl/1_my_robot v2_link2_7_1_Body1.stl" scale="0.00100 0.00100 0.00100"/>
      </geometry>
    </visual>
  </link>
  <link name="link3_motor">
    <collision name="mesh_link3_motor_collision">
      <origin rpy="0.00000 0.00000 0.00000" xyz="-0.09900 0.00000 -0.30200"/>
      <geometry>
        <mesh filename="../meshes/stl/1_my_robot v2_link3_motor_1_Body1.stl" scale="0.00100 0.00100 0.00100"/>
      </geometry>
    </collision>
    <visual name="mesh_link3_motor">
      <material name="None"/>
      <origin rpy="0.00000 0.00000 0.00000" xyz="-0.09900 0.00000 -0.30200"/>
      <geometry>
        <mesh filename="../meshes/stl/1_my_robot v2_link3_motor_1_Body1.stl" scale="0.00100 0.00100 0.00100"/>
      </geometry>
    </visual>
  </link>
  <link name="link3_1">
    <collision name="mesh_link3_1_collision">
      <origin rpy="0.00000 0.00000 0.00000" xyz="-0.09900 0.00000 -0.34105"/>
      <geometry>
        <mesh filename="../meshes/stl/1_my_robot v2_link3_1_1_Body1.stl" scale="0.00100 0.00100 0.00100"/>
      </geometry>
    </collision>
    <visual name="mesh_link3_1">
      <material name="None"/>
      <origin rpy="0.00000 0.00000 0.00000" xyz="-0.09900 0.00000 -0.34105"/>
      <geometry>
        <mesh filename="../meshes/stl/1_my_robot v2_link3_1_1_Body1.stl" scale="0.00100 0.00100 0.00100"/>
      </geometry>
    </visual>
  </link>
</robot>